#define _CRT_SECURE_NO_WARNINGS 1
#include<iostream>
#include<windows.h>
using namespace std;

// 服务器开发中通常使用的异常继承体系
class Exception
{
public:
	Exception(const string& errmsg, int id)
		:_errmsg(errmsg)
		, _id(id)
	{}

	virtual string what() const
	{
		return _errmsg;
	}
protected:
	string _errmsg; // 错误描述
	int _id;		// 错误编号
};

class SqlException : public Exception
{
public:
	SqlException(const string& errmsg, int id, const string& sql)
		:Exception(errmsg, id)
		, _sql(sql)
	{}

	virtual string what() const
	{
		string str = "SqlException:";
		str += _errmsg;
		str += "->";
		str += _sql;

		return str;
	}

private:
	const string _sql;
};

class CacheException : public Exception
{
public:
	CacheException(const string& errmsg, int id)
		:Exception(errmsg, id)
	{}

	virtual string what() const
	{
		string str = "CacheException:";
		str += _errmsg;
		return str;
	}
};

class HttpServerException : public Exception
{
public:
	HttpServerException(const string& errmsg, int id, const string& type)
		:Exception(errmsg, id)
		, _type(type)
	{}

	virtual string what() const
	{
		string str = "HttpServerException:";
		str += _type;
		str += ":";
		str += _errmsg;

		return str;
	}

private:
	const string _type;
};

void SQLMgr()
{
	srand(time(0));
	if (rand() % 7 == 0)
	{
		throw SqlException("权限不足", 100, "select * from name = '张三'");
	}

	//throw "xxxxxx";
}

void CacheMgr()
{
	srand(time(0));
	if (rand() % 5 == 0)
	{
		throw CacheException("权限不足", 100);
	}
	else if (rand() % 6 == 0)
	{
		throw CacheException("数据不存在", 101);
	}

	SQLMgr();
}

void HttpServer()
{
	// ...
	srand(time(0));
	if (rand() % 3 == 0)
	{
		throw HttpServerException("请求资源不存在", 100, "get");
	}
	else if (rand() % 4 == 0)
	{
		throw HttpServerException("权限不足", 101, "post");
	}

	CacheMgr();
}

//int main()
//{
//	while (1)
//	{
//		// 16：05继续
//		Sleep(500);
//
//		try {
//			HttpServer();
//		}
//		catch (const Exception& e) // 这里捕获父类对象就可以
//		{
//		/*	int n = 10;
//			while(e._erid == 3 && n--)
//			{
//				// 重试
//				Seed
//			}*/
//
//			// 多态
//			cout << e.what() << endl;
//		}
//		catch (...)
//		{
//			cout << "Unkown Exception" << endl;
//		}
//	}
//
//	return 0;
//}

//double Division(int a, int b)
//{
//	// 当b == 0时抛出异常
//	if (b == 0)
//	{
//		throw "Division by zero condition!";
//	}
//	return (double)a / (double)b;
//}
//
//void Func()
//{
//	// 这里可以看到如果发生除0错误抛出异常，另外下面的array没有得到释放。
//	// 所以这里捕获异常后并不处理异常，异常还是交给外面处理，这里捕获了再
//	// 重新抛出去。
//	int* array1 = new int[10];
//	int* array2 = new int[20];
//
//	// 异常安全问题
//	try {
//		int len, time;
//		cin >> len >> time;
//		cout << Division(len, time) << endl;
//	}
//	catch (...)
//	{
//		cout << "delete []" << array1 << endl;
//		delete[] array1;
//
//		cout << "delete []" << array2 << endl;
//		delete[] array2;
//
//		throw;  // 捕到什么抛什么
//	}
//	/*catch (const char* errmsg)
//	{
//		cout << "delete []" << array << endl;
//		delete[] array;
//
//		throw errmsg;
//	}*/
//
//	cout << "delete []" << array1 << endl;
//	delete[] array1;
//
//	cout << "delete []" << array2 << endl;
//	delete[] array2;
//}
//
//int main()
//{
//	try
//	{
//		Func();
//	}
//	catch (const char* errmsg)
//	{
//		cout << errmsg << endl;
//	}
//	catch (const exception& e)
//	{
//		cout << e.what() << endl;
//	}
//
//	return 0;
//}

//double Division(int a, int b) throw()
//{
//	// 当b == 0时抛出异常
//	if (b == 0)
//	{
//		throw "Division by zero condition!";
//	}
//	return (double)a / (double)b;
//}
//
//void Func() throw(const char*)
//{
//	int len, time;
//	cin >> len >> time;
//	cout << Division(len, time) << endl;
//}
//
//int main()
//{
//	try
//	{
//		Func();
//	}
//	catch (const char* errmsg)
//	{
//		cout << errmsg << endl;
//	}
//	catch (const exception& e)
//	{
//		cout << e.what() << endl;
//	}
//
//	return 0;
//}

double Division(int a, int b)
{
	// 当b == 0时抛出异常
	if (b == 0)
	{
		throw "Division by zero condition!";
	}

	return (double)a / (double)b;
}

void Func()
{
	int len, time;
	cin >> len >> time;
	cout << Division(len, time) << endl;
}

int main()
{
	try
	{
		Func();
	}
	catch (const char errmsg)
	{
		cout << errmsg << endl;
	}
	catch (const exception& e)
	{
		cout << e.what() << endl;
	}

	return 0;
}

